File: Input XRD/1_Ti64Si.csv
[Measurement conditions]
Sample identification,LSM Long
Comment - 1,"LSM Long"
Comment - 2,"Configuration=MPSS New Configuration, Owner=User-1, Creation date=10/27/2010 9:00:11 AM"
Comment - 3,"Goniometer=PW3050/60 (Theta/Theta); Minimum step size 2Theta:0.001; Minimum step size Omega:0.001"
Comment - 4,"Sample stage=Multi purpose sample stage; Minimum step size Phi:2.5"
Comment - 5,"Diffractometer system=XPERT-PRO"
Comment - 6,"Measurement program=C:\PANalytical\Data Collector\Programs\ahansen\Ti Long Scan.xrdmp, Identifier={EF68F247-B130-4A84-9FC1-7BC14FCD5EAC}"
Comment - 7,"PHD Lower Level = 6.04 (keV), PHD Upper Level = 12.80 (keV)"
Anode material,Cu
K-Alpha1 wavelength,1.5405980
K-Alpha2 wavelength,1.5444260
Ratio K-Alpha2/K-Alpha1,0.500
Divergence slit,Fixed,0.109
Receiving slit,0.10
Monochromator used,NO
Generator voltage, 45
Tube current, 40
File date and time,23/Jun/2021 12:46
Unit cell,
h k l, 0 0 0
Temperature [K],298
Scan axis,Gonio
Scan range,10.0000,150.0040
Scan step size,0.0040000
No. of points, 35001
Scan type,CONTINUOUS
Time per step,5.080
[Scan points]
Angle,Intensity
10.0020,0.0
10.0980,-6.0
10.1940,4.0
10.2900,-6.0
10.3860,5.0
10.4820,-7.0
10.5780,-3.0
10.6740,-4.0
10.7700,3.0
10.8660,4.0
10.9620,-5.0
11.0580,-6.0
11.1540,9.0
11.2500,8.0
11.3460,-4.0
11.4420,-2.0
11.5380,-2.0
11.6340,-5.0
11.7300,-4.0
11.8260,0.0
11.9220,-4.0
12.0180,4.0
12.1140,-3.0
12.2100,-1.0
12.3060,-2.0
12.4020,0.0
12.4980,3.0
12.5940,7.0
12.6900,-10.0
12.7860,-6.0
12.8820,-2.0
12.9780,6.0
13.0740,6.0
13.1700,-13.0
13.2660,1.0
13.3620,-3.0
13.4580,-5.0
13.5540,-8.0
13.6500,1.0
13.7460,8.0
13.8420,5.0
13.9380,-5.0
14.0340,-6.0
14.1300,-8.0
14.2260,-6.0
14.3220,5.0
14.4180,-2.0
14.5140,4.0
14.6100,-9.0
14.7060,-1.0
14.8020,3.0
14.8980,3.0
14.9940,6.0
15.0900,2.0
15.1860,9.0
15.2820,10.0
15.3780,4.0
15.4740,-1.0
15.5700,0.0
15.6660,0.0
15.7620,-1.0
15.8580,3.0
15.9540,-1.0
16.0500,0.0
16.1460,7.0
16.2420,-6.0
16.3380,-1.0
16.4340,1.0
16.5300,6.0
16.6260,13.0
16.7220,-2.0
16.8180,-3.0
16.9140,2.0
17.0100,-9.0
17.1060,-1.0
17.2020,-1.0
17.2980,-2.0
17.3940,-7.0
17.4900,5.0
17.5860,1.0
17.6820,3.0
17.7780,-5.0
17.8740,-5.0
17.9700,-2.0
18.0660,-6.0
18.1620,-4.0
18.2580,10.0
18.3540,-7.0
18.4500,2.0
18.5460,8.0
18.6420,-2.0
18.7380,2.0
18.8340,-4.0
18.9300,-4.0
19.0260,-3.0
19.1220,-1.0
19.2180,11.0
19.3140,8.0
19.4100,10.0
19.5060,1.0
19.6020,-5.0
19.6980,-4.0
19.7940,5.0
19.8900,0.0
19.9860,-6.0
20.0820,-9.0
20.1780,-1.0
20.2740,11.0
20.3700,2.0
20.4660,0.0
20.5620,-8.0
20.6580,-1.0
20.7540,2.0
20.8500,-3.0
20.9460,-4.0
21.0420,3.0
21.1380,0.0
21.2340,-2.0
21.3300,-1.0
21.4260,3.0
21.5220,-2.0
21.6180,5.0
21.7140,-5.0
21.8100,-4.0
21.9060,6.0
22.0020,-2.0
22.0980,-2.0
22.1940,2.0
22.2900,-5.0
22.3860,0.0
22.4820,0.0
22.5780,4.0
22.6740,-5.0
22.7700,0.0
22.8660,-1.0
22.9620,1.0
23.0580,-6.0
23.1540,11.0
23.2500,2.0
23.3460,0.0
23.4420,-3.0
23.5380,0.0
23.6340,1.0
23.7300,6.0
23.8260,1.0
23.9220,7.0
24.0180,3.0
24.1140,1.0
24.2100,-4.0
24.3060,3.0
24.4020,-4.0
24.4980,4.0
24.5940,5.0
24.6900,-3.0
24.7860,4.0
24.8820,4.0
24.9780,9.0
25.0740,-2.0
25.1700,0.0
25.2660,5.0
25.3620,6.0
25.4580,1.0
25.5540,-2.0
25.6500,3.0
25.7460,-5.0
25.8420,3.0
25.9380,-4.0
26.0340,-2.0
26.1300,-3.0
26.2260,-1.0
26.3220,-2.0
26.4180,1.0
26.5140,1.0
26.6100,3.0
26.7060,0.0
26.8020,3.0
26.8980,-4.0
26.9940,3.0
27.0900,-4.0
27.1860,1.0
27.2820,3.0
27.3780,-3.0
27.4740,0.0
27.5700,6.0
27.6660,2.0
27.7620,9.0
27.8580,-3.0
27.9540,-1.0
28.0500,-7.0
28.1460,-2.0
28.2420,1.0
28.3380,-5.0
28.4340,-5.0
28.5300,-2.0
28.6260,-4.0
28.7220,-6.0
28.8180,-5.0
28.9140,0.0
29.0100,4.0
29.1060,-3.0
29.2020,-2.0
29.2980,-7.0
29.3940,-2.0
29.4900,3.0
29.5860,-5.0
29.6820,6.0
29.7780,-1.0
29.8740,-1.0
29.9700,0.0
30.0660,-2.0
30.1620,3.0
30.2580,-5.0
30.3540,-4.0
30.4500,5.0
30.5460,10.0
30.6420,3.0
30.7380,1.0
30.8340,4.0
30.9300,4.0
31.0260,-6.0
31.1220,-3.0
31.2180,-5.0
31.3140,3.0
31.4100,-1.0
31.5060,-8.0
31.6020,-3.0
31.6980,-1.0
31.7940,12.0
31.8900,0.0
31.9860,-1.0
32.0820,-8.0
32.1780,3.0
32.2740,-2.0
32.3700,-5.0
32.4660,-3.0
32.5620,-5.0
32.6580,-3.0
32.7540,5.0
32.8500,2.0
32.9460,2.0
33.0420,9.0
33.1380,-1.0
33.2340,2.0
33.3300,2.0
33.4260,-1.0
33.5220,2.0
33.6180,0.0
33.7140,-4.0
33.8100,-5.0
33.9060,-2.0
34.0020,0.0
34.0980,-1.0
34.1940,8.0
34.2900,5.0
34.3860,0.0
34.4820,-2.0
34.5780,6.0
34.6740,6.0
34.7700,1.0
34.8660,4.0
34.9620,8.0
35.0580,34.0
35.1540,255.0
35.2500,183.0
35.3460,15.0
35.4420,8.0
35.5380,8.0
35.6340,-7.0
35.7300,2.0
35.8260,3.0
35.9220,-4.0
36.0180,5.0
36.1140,-1.0
36.2100,4.0
36.3060,3.0
36.4020,-3.0
36.4980,10.0
36.5940,-4.0
36.6900,4.0
36.7860,2.0
36.8820,2.0
36.9780,10.0
37.0740,11.0
37.1700,-3.0
37.2660,7.0
37.3620,2.0
37.4580,-1.0
37.5540,-5.0
37.6500,13.0
37.7460,-1.0
37.8420,-8.0
37.9380,7.0
38.0340,0.0
38.1300,4.0
38.2260,28.0
38.3220,152.0
38.4180,68.0
38.5140,5.0
38.6100,0.0
38.7060,11.0
38.8020,4.0
38.8980,6.0
38.9940,5.0
39.0900,-1.0
39.1860,-1.0
39.2820,6.0
39.3780,21.0
39.4740,27.0
39.5700,10.0
39.6660,3.0
39.7620,5.0
39.8580,3.0
39.9540,11.0
40.0500,57.0
40.1460,173.0
40.2420,1504.0
40.3380,790.0
40.4340,122.0
40.5300,17.0
40.6260,6.0
40.7220,10.0
40.8180,3.0
40.9140,1.0
41.0100,4.0
41.1060,16.0
41.2020,-5.0
41.2980,-2.0
41.3940,0.0
41.4900,0.0
41.5860,1.0
41.6820,-3.0
41.7780,0.0
41.8740,-5.0
41.9700,-2.0
42.0660,4.0
42.1620,-3.0
42.2580,-1.0
42.3540,1.0
42.4500,4.0
42.5460,6.0
42.6420,3.0
42.7380,-6.0
42.8340,1.0
42.9300,1.0
43.0260,-1.0
43.1220,2.0
43.2180,1.0
43.3140,2.0
43.4100,4.0
43.5060,-2.0
43.6020,4.0
43.6980,0.0
43.7940,-1.0
43.8900,1.0
43.9860,2.0
44.0820,-1.0
44.1780,3.0
44.2740,4.0
44.3700,2.0
44.4660,2.0
44.5620,5.0
44.6580,-2.0
44.7540,5.0
44.8500,-1.0
44.9460,-3.0
45.0420,0.0
45.1380,-6.0
45.2340,-1.0
45.3300,5.0
45.4260,3.0
45.5220,-7.0
45.6180,3.0
45.7140,-7.0
45.8100,-9.0
45.9060,-2.0
46.0020,-2.0
46.0980,-1.0
46.1940,3.0
46.2900,1.0
46.3860,9.0
46.4820,3.0
46.5780,8.0
46.6740,11.0
46.7700,2.0
46.8660,4.0
46.9620,2.0
47.0580,-3.0
47.1540,4.0
47.2500,1.0
47.3460,3.0
47.4420,-5.0
47.5380,1.0
47.6340,3.0
47.7300,3.0
47.8260,3.0
47.9220,2.0
48.0180,4.0
48.1140,0.0
48.2100,-1.0
48.3060,-1.0
48.4020,5.0
48.4980,9.0
48.5940,4.0
48.6900,-6.0
48.7860,2.0
48.8820,-2.0
48.9780,2.0
49.0740,-5.0
49.1700,-1.0
49.2660,-1.0
49.3620,-5.0
49.4580,4.0
49.5540,-3.0
49.6500,7.0
49.7460,-2.0
49.8420,6.0
49.9380,3.0
50.0340,13.0
50.1300,9.0
50.2260,-1.0
50.3220,5.0
50.4180,0.0
50.5140,2.0
50.6100,8.0
50.7060,-1.0
50.8020,-4.0
50.8980,1.0
50.9940,6.0
51.0900,5.0
51.1860,1.0
51.2820,2.0
51.3780,4.0
51.4740,3.0
51.5700,2.0
51.6660,8.0
51.7620,3.0
51.8580,2.0
51.9540,1.0
52.0500,2.0
52.1460,3.0
52.2420,0.0
52.3380,8.0
52.4340,6.0
52.5300,12.0
52.6260,7.0
52.7220,9.0
52.8180,7.0
52.9140,18.0
53.0100,309.0
53.1060,298.0
53.2020,197.0
53.2980,39.0
53.3940,13.0
53.4900,5.0
53.5860,0.0
53.6820,-2.0
53.7780,-2.0
53.8740,5.0
53.9700,1.0
54.0660,-3.0
54.1620,3.0
54.2580,3.0
54.3540,-7.0
54.4500,3.0
54.5460,5.0
54.6420,4.0
54.7380,-5.0
54.8340,2.0
54.9300,-1.0
55.0260,-7.0
55.1220,-4.0
55.2180,-8.0
55.3140,3.0
55.4100,-1.0
55.5060,-5.0
55.6020,-3.0
55.6980,6.0
55.7940,0.0
55.8900,-6.0
55.9860,2.0
56.0820,-3.0
56.1780,0.0
56.2740,-5.0
56.3700,5.0
56.4660,0.0
56.5620,-6.0
56.6580,0.0
56.7540,-4.0
56.8500,-4.0
56.9460,1.0
57.0420,12.0
57.1380,0.0
57.2340,9.0
57.3300,0.0
57.4260,3.0
57.5220,-4.0
57.6180,-3.0
57.7140,5.0
57.8100,1.0
57.9060,3.0
58.0020,0.0
58.0980,-3.0
58.1940,9.0
58.2900,6.0
58.3860,-3.0
58.4820,-7.0
58.5780,4.0
58.6740,4.0
58.7700,-3.0
58.8660,-2.0
58.9620,-3.0
59.0580,0.0
59.1540,-2.0
59.2500,4.0
59.3460,9.0
59.4420,-4.0
59.5380,10.0
59.6340,0.0
59.7300,2.0
59.8260,1.0
59.9220,3.0
60.0180,3.0
60.1140,-1.0
60.2100,0.0
60.3060,4.0
60.4020,2.0
60.4980,9.0
60.5940,3.0
60.6900,2.0
60.7860,0.0
60.8820,6.0
60.9780,-3.0
61.0740,8.0
61.1700,3.0
61.2660,-5.0
61.3620,5.0
61.4580,2.0
61.5540,4.0
61.6500,1.0
61.7460,8.0
61.8420,-2.0
61.9380,-1.0
62.0340,1.0
62.1300,-1.0
62.2260,-1.0
62.3220,0.0
62.4180,-3.0
62.5140,-3.0
62.6100,0.0
62.7060,5.0
62.8020,-3.0
62.8980,3.0
62.9940,4.0
63.0900,18.0
63.1860,74.0
63.2820,89.0
63.3780,55.0
63.4740,42.0
63.5700,24.0
63.6660,-3.0
63.7620,0.0
63.8580,0.0
63.9540,1.0
64.0500,4.0
64.1460,-6.0
64.2420,-4.0
64.3380,3.0
64.4340,0.0
64.5300,1.0
64.6260,0.0
64.7220,2.0
64.8180,0.0
64.9140,0.0
65.0100,-4.0
65.1060,1.0
65.2020,7.0
65.2980,4.0
65.3940,-4.0
65.4900,3.0
65.5860,-1.0
65.6820,-5.0
65.7780,2.0
65.8740,-4.0
65.9700,0.0
66.0660,3.0
66.1620,2.0
66.2580,4.0
66.3540,1.0
66.4500,-2.0
66.5460,1.0
66.6420,0.0
66.7380,-2.0
66.8340,-2.0
66.9300,1.0
67.0260,11.0
67.1220,1.0
67.2180,5.0
67.3140,-3.0
67.4100,1.0
67.5060,7.0
67.6020,6.0
67.6980,0.0
67.7940,3.0
67.8900,12.0
67.9860,5.0
68.0820,6.0
68.1780,5.0
68.2740,8.0
68.3700,7.0
68.4660,7.0
68.5620,4.0
68.6580,6.0
68.7540,1.0
68.8500,6.0
68.9460,-3.0
69.0420,7.0
69.1380,3.0
69.2340,-2.0
69.3300,4.0
69.4260,5.0
69.5220,9.0
69.6180,3.0
69.7140,4.0
69.8100,0.0
69.9060,4.0
70.0020,6.0
70.0980,8.0
70.1940,2.0
70.2900,4.0
70.3860,8.0
70.4820,5.0
70.5780,46.0
70.6740,327.0
70.7700,155.0
70.8660,146.0
70.9620,99.0
71.0580,22.0
71.1540,9.0
71.2500,-3.0
71.3460,0.0
71.4420,-7.0
71.5380,7.0
71.6340,4.0
71.7300,15.0
71.8260,-1.0
71.9220,3.0
72.0180,3.0
72.1140,-1.0
72.2100,-6.0
72.3060,2.0
72.4020,-2.0
72.4980,-2.0
72.5940,2.0
72.6900,-4.0
72.7860,-1.0
72.8820,0.0
72.9780,-1.0
73.0740,-4.0
73.1700,-5.0
73.2660,-2.0
73.3620,-6.0
73.4580,-4.0
73.5540,1.0
73.6500,-2.0
73.7460,-7.0
73.8420,1.0
73.9380,7.0
74.0340,4.0
74.1300,3.0
74.2260,0.0
74.3220,3.0
74.4180,14.0
74.5140,46.0
74.6100,28.0
74.7060,18.0
74.8020,24.0
74.8980,4.0
74.9940,4.0
75.0900,9.0
75.1860,3.0
75.2820,1.0
75.3780,-2.0
75.4740,-2.0
75.5700,4.0
75.6660,1.0
75.7620,4.0
75.8580,9.0
75.9540,2.0
76.0500,8.0
76.1460,8.0
76.2420,10.0
76.3380,13.0
76.4340,83.0
76.5300,238.0
76.6260,59.0
76.7220,105.0
76.8180,40.0
76.9140,25.0
77.0100,6.0
77.1060,5.0
77.2020,-4.0
77.2980,-1.0
77.3940,-1.0
77.4900,13.0
77.5860,8.0
77.6820,17.0
77.7780,26.0
77.8740,41.0
77.9700,24.0
78.0660,33.0
78.1620,6.0
78.2580,2.0
78.3540,5.0
78.4500,-4.0
78.5460,2.0
78.6420,8.0
78.7380,3.0
78.8340,5.0
78.9300,6.0
79.0260,1.0
79.1220,7.0
79.2180,10.0
79.3140,5.0
79.4100,4.0
79.5060,1.0
79.6020,13.0
79.6980,3.0
79.7940,14.0
79.8900,3.0
79.9860,11.0
80.0820,12.0
80.1780,-4.0
80.2740,5.0
80.3700,9.0
80.4660,2.0
80.5620,-2.0
80.6580,1.0
80.7540,2.0
80.8500,11.0
80.9460,5.0
81.0420,-3.0
81.1380,-1.0
81.2340,-2.0
81.3300,-7.0
81.4260,6.0
81.5220,14.0
81.6180,2.0
81.7140,5.0
81.8100,-2.0
81.9060,10.0
82.0020,0.0
82.0980,-3.0
82.1940,12.0
82.2900,5.0
82.3860,4.0
82.4820,5.0
82.5780,10.0
82.6740,-1.0
82.7700,10.0
82.8660,5.0
82.9620,0.0
83.0580,0.0
83.1540,-2.0
83.2500,8.0
83.3460,2.0
83.4420,1.0
83.5380,1.0
83.6340,5.0
83.7300,-1.0
83.8260,2.0
83.9220,-3.0
84.0180,2.0
84.1140,0.0
84.2100,-8.0
84.3060,3.0
84.4020,-4.0
84.4980,2.0
84.5940,3.0
84.6900,-2.0
84.7860,4.0
84.8820,0.0
84.9780,0.0
85.0740,3.0
85.1700,-5.0
85.2660,1.0
85.3620,7.0
85.4580,-6.0
85.5540,4.0
85.6500,-10.0
85.7460,2.0
85.8420,-8.0
85.9380,2.0
86.0340,-7.0
86.1300,-10.0
86.2260,2.0
86.3220,-1.0
86.4180,-10.0
86.5140,-6.0
86.6100,-2.0
86.7060,4.0
86.8020,1.0
86.8980,-1.0
86.9940,-1.0
87.0900,11.0
87.1860,6.0
87.2820,6.0
87.3780,9.0
87.4740,2.0
87.5700,-1.0
87.6660,-1.0
87.7620,7.0
87.8580,1.0
87.9540,6.0
88.0500,5.0
88.1460,2.0
88.2420,-4.0
88.3380,2.0
88.4340,7.0
88.5300,-7.0
88.6260,5.0
88.7220,1.0
88.8180,-5.0
88.9140,3.0
89.0100,2.0
89.1060,1.0
89.2020,-1.0
89.2980,3.0
89.3940,-1.0
89.4900,8.0
89.5860,15.0
89.6820,5.0
89.7780,5.0
89.8740,0.0
89.9700,-1.0
90.0660,9.0
90.1620,2.0
90.2580,-2.0
90.3540,-4.0
90.4500,11.0
90.5460,12.0
90.6420,1.0
90.7380,4.0
90.8340,-1.0
90.9300,-1.0
91.0260,6.0
91.1220,-1.0
91.2180,0.0
91.3140,6.0
91.4100,-1.0
91.5060,-1.0
91.6020,11.0
91.6980,1.0
91.7940,2.0
91.8900,-3.0
91.9860,6.0
92.0820,0.0
92.1780,7.0
92.2740,8.0
92.3700,3.0
92.4660,0.0
92.5620,10.0
92.6580,6.0
92.7540,9.0
92.8500,11.0
92.9460,10.0
93.0420,9.0
93.1380,5.0
93.2340,0.0
93.3300,-1.0
93.4260,2.0
93.5220,-6.0
93.6180,-1.0
93.7140,-5.0
93.8100,3.0
93.9060,-2.0
94.0020,-2.0
94.0980,1.0
94.1940,8.0
94.2900,-2.0
94.3860,-2.0
94.4820,-1.0
94.5780,-2.0
94.6740,-5.0
94.7700,-2.0
94.8660,-2.0
94.9620,3.0
95.0580,1.0
95.1540,1.0
95.2500,0.0
95.3460,-5.0
95.4420,1.0
95.5380,3.0
95.6340,-3.0
95.7300,1.0
95.8260,1.0
95.9220,4.0
96.0180,0.0
96.1140,6.0
96.2100,1.0
96.3060,2.0
96.4020,4.0
96.4980,-3.0
96.5940,0.0
96.6900,-1.0
96.7860,1.0
96.8820,-2.0
96.9780,3.0
97.0740,-5.0
97.1700,-3.0
97.2660,2.0
97.3620,2.0
97.4580,1.0
97.5540,3.0
97.6500,1.0
97.7460,-8.0
97.8420,-7.0
97.9380,-1.0
98.0340,-5.0
98.1300,-5.0
98.2260,1.0
98.3220,0.0
98.4180,3.0
98.5140,-8.0
98.6100,-6.0
98.7060,2.0
98.8020,-3.0
98.8980,4.0
98.9940,-5.0
99.0900,8.0
99.1860,-1.0
99.2820,-3.0
99.3780,-4.0
99.4740,-1.0
99.5700,-3.0
99.6660,-2.0
99.7620,1.0
99.8580,7.0
99.9540,-1.0
100.0500,8.0
100.1460,3.0
100.2420,5.0
100.3380,4.0
100.4340,-1.0
100.5300,1.0
100.6260,-1.0
100.7220,1.0
100.8180,10.0
100.9140,-3.0
101.0100,-5.0
101.1060,4.0
101.2020,3.0
101.2980,7.0
101.3940,2.0
101.4900,0.0
101.5860,3.0
101.6820,1.0
101.7780,0.0
101.8740,8.0
101.9700,6.0
102.0660,1.0
102.1620,4.0
102.2580,4.0
102.3540,0.0
102.4500,8.0
102.5460,14.0
102.6420,24.0
102.7380,69.0
102.8340,50.0
102.9300,26.0
103.0260,23.0
103.1220,36.0
103.2180,24.0
103.3140,4.0
103.4100,8.0
103.5060,-1.0
103.6020,5.0
103.6980,-6.0
103.7940,5.0
103.8900,0.0
103.9860,-3.0
104.0820,-4.0
104.1780,-1.0
104.2740,-3.0
104.3700,0.0
104.4660,1.0
104.5620,-10.0
104.6580,3.0
104.7540,0.0
104.8500,-1.0
104.9460,-5.0
105.0420,4.0
105.1380,0.0
105.2340,-11.0
105.3300,6.0
105.4260,5.0
105.5220,6.0
105.6180,0.0
105.7140,-1.0
105.8100,7.0
105.9060,-3.0
106.0020,5.0
106.0980,-7.0
106.1940,2.0
106.2900,-4.0
106.3860,0.0
106.4820,17.0
106.5780,30.0
106.6740,11.0
106.7700,5.0
106.8660,8.0
106.9620,14.0
107.0580,16.0
107.1540,0.0
107.2500,5.0
107.3460,3.0
107.4420,-5.0
107.5380,6.0
107.6340,-6.0
107.7300,-6.0
107.8260,3.0
107.9220,2.0
108.0180,4.0
108.1140,3.0
108.2100,0.0
108.3060,-10.0
108.4020,-10.0
108.4980,1.0
108.5940,9.0
108.6900,4.0
108.7860,-4.0
108.8820,0.0
108.9780,4.0
109.0740,4.0
109.1700,4.0
109.2660,4.0
109.3620,8.0
109.4580,3.0
109.5540,11.0
109.6500,33.0
109.7460,63.0
109.8420,72.0
109.9380,48.0
110.0340,38.0
110.1300,37.0
110.2260,33.0
110.3220,43.0
110.4180,26.0
110.5140,12.0
110.6100,7.0
110.7060,5.0
110.8020,-2.0
110.8980,1.0
110.9940,0.0
111.0900,2.0
111.1860,2.0
111.2820,1.0
111.3780,5.0
111.4740,3.0
111.5700,-4.0
111.6660,3.0
111.7620,3.0
111.8580,-3.0
111.9540,2.0
112.0500,3.0
112.1460,-1.0
112.2420,6.0
112.3380,-1.0
112.4340,1.0
112.5300,2.0
112.6260,0.0
112.7220,2.0
112.8180,-14.0
112.9140,-5.0
113.0100,9.0
113.1060,-5.0
113.2020,0.0
113.2980,-5.0
113.3940,-6.0
113.4900,1.0
113.5860,-9.0
113.6820,-5.0
113.7780,-1.0
113.8740,0.0
113.9700,-5.0
114.0660,0.0
114.1620,2.0
114.2580,10.0
114.3540,6.0
114.4500,11.0
114.5460,12.0
114.6420,47.0
114.7380,16.0
114.8340,11.0
114.9300,0.0
115.0260,13.0
115.1220,12.0
115.2180,10.0
115.3140,6.0
115.4100,2.0
115.5060,6.0
115.6020,-4.0
115.6980,6.0
115.7940,4.0
115.8900,0.0
115.9860,1.0
116.0820,-1.0
116.1780,0.0
116.2740,1.0
116.3700,2.0
116.4660,-6.0
116.5620,-1.0
116.6580,-3.0
116.7540,0.0
116.8500,1.0
116.9460,-2.0
117.0420,-4.0
117.1380,7.0
117.2340,-4.0
117.3300,-9.0
117.4260,20.0
117.5220,-4.0
117.6180,2.0
117.7140,5.0
117.8100,-6.0
117.9060,-6.0
118.0020,0.0
118.0980,-3.0
118.1940,-1.0
118.2900,0.0
118.3860,-1.0
118.4820,-1.0
118.5780,-2.0
118.6740,1.0
118.7700,1.0
118.8660,-2.0
118.9620,2.0
119.0580,0.0
119.1540,0.0
119.2500,-4.0
119.3460,5.0
119.4420,-6.0
119.5380,2.0
119.6340,-9.0
119.7300,2.0
119.8260,1.0
119.9220,2.0
120.0180,-3.0
120.1140,9.0
120.2100,9.0
120.3060,3.0
120.4020,4.0
120.4980,5.0
120.5940,5.0
120.6900,-2.0
120.7860,0.0
120.8820,3.0
120.9780,-2.0
121.0740,-3.0
121.1700,-2.0
121.2660,1.0
121.3620,-3.0
121.4580,1.0
121.5540,-3.0
121.6500,-3.0
121.7460,8.0
121.8420,0.0
121.9380,2.0
122.0340,-7.0
122.1300,0.0
122.2260,-1.0
122.3220,3.0
122.4180,24.0
122.5140,21.0
122.6100,18.0
122.7060,3.0
122.8020,4.0
122.8980,7.0
122.9940,11.0
123.0900,1.0
123.1860,2.0
123.2820,5.0
123.3780,6.0
123.4740,0.0
123.5700,-1.0
123.6660,9.0
123.7620,-3.0
123.8580,3.0
123.9540,0.0
124.0500,1.0
124.1460,-2.0
124.2420,4.0
124.3380,-3.0
124.4340,-3.0
124.5300,-1.0
124.6260,-2.0
124.7220,5.0
124.8180,1.0
124.9140,-10.0
125.0100,7.0
125.1060,-1.0
125.2020,4.0
125.2980,4.0
125.3940,8.0
125.4900,-3.0
125.5860,5.0
125.6820,-6.0
125.7780,1.0
125.8740,13.0
125.9700,-2.0
126.0660,-1.0
126.1620,4.0
126.2580,1.0
126.3540,-7.0
126.4500,-1.0
126.5460,-5.0
126.6420,9.0
126.7380,14.0
126.8340,17.0
126.9300,1.0
127.0260,6.0
127.1220,6.0
127.2180,-1.0
127.3140,15.0
127.4100,-5.0
127.5060,3.0
127.6020,9.0
127.6980,5.0
127.7940,3.0
127.8900,2.0
127.9860,-4.0
128.0820,-4.0
128.1780,-4.0
128.2740,-1.0
128.3700,4.0
128.4660,-3.0
128.5620,-3.0
128.6580,-6.0
128.7540,-1.0
128.8500,0.0
128.9460,9.0
129.0420,8.0
129.1380,1.0
129.2340,5.0
129.3300,12.0
129.4260,5.0
129.5220,4.0
129.6180,4.0
129.7140,0.0
129.8100,-9.0
129.9060,5.0
130.0020,-3.0
130.0980,7.0
130.1940,-4.0
130.2900,6.0
130.3860,3.0
130.4820,18.0
130.5780,30.0
130.6740,25.0
130.7700,36.0
130.8660,17.0
130.9620,27.0
131.0580,10.0
131.1540,2.0
131.2500,8.0
131.3460,18.0
131.4420,17.0
131.5380,22.0
131.6340,3.0
131.7300,11.0
131.8260,6.0
131.9220,7.0
132.0180,8.0
132.1140,5.0
132.2100,3.0
132.3060,2.0
132.4020,-1.0
132.4980,1.0
132.5940,1.0
132.6900,-2.0
132.7860,1.0
132.8820,-1.0
132.9780,4.0
133.0740,-1.0
133.1700,3.0
133.2660,7.0
133.3620,-1.0
133.4580,1.0
133.5540,2.0
133.6500,-5.0
133.7460,-1.0
133.8420,7.0
133.9380,-1.0
134.0340,-3.0
134.1300,-2.0
134.2260,7.0
134.3220,-1.0
134.4180,-6.0
134.5140,11.0
134.6100,5.0
134.7060,2.0
134.8020,-4.0
134.8980,-5.0
134.9940,4.0
135.0900,6.0
135.1860,10.0
135.2820,-4.0
135.3780,9.0
135.4740,7.0
135.5700,-1.0
135.6660,4.0
135.7620,6.0
135.8580,4.0
135.9540,-8.0
136.0500,5.0
136.1460,5.0
136.2420,-4.0
136.3380,6.0
136.4340,2.0
136.5300,4.0
136.6260,2.0
136.7220,6.0
136.8180,-6.0
136.9140,-2.0
137.0100,3.0
137.1060,2.0
137.2020,-6.0
137.2980,0.0
137.3940,1.0
137.4900,5.0
137.5860,-9.0
137.6820,7.0
137.7780,2.0
137.8740,-2.0
137.9700,-4.0
138.0660,-3.0
138.1620,7.0
138.2580,-3.0
138.3540,3.0
138.4500,2.0
138.5460,-2.0
138.6420,1.0
138.7380,4.0
138.8340,1.0
138.9300,3.0
139.0260,1.0
139.1220,5.0
139.2180,4.0
139.3140,-3.0
139.4100,5.0
139.5060,-6.0
139.6020,0.0
139.6980,-4.0
139.7940,-8.0
139.8900,12.0
139.9860,-3.0
140.0820,0.0
140.1780,7.0
140.2740,7.0
140.3700,22.0
140.4660,22.0
140.5620,38.0
140.6580,18.0
140.7540,36.0
140.8500,25.0
140.9460,23.0
141.0420,23.0
141.1380,19.0
141.2340,18.0
141.3300,30.0
141.4260,17.0
141.5220,30.0
141.6180,21.0
141.7140,8.0
141.8100,20.0
141.9060,16.0
142.0020,10.0
142.0980,9.0
142.1940,6.0
142.2900,6.0
142.3860,7.0
142.4820,-2.0
142.5780,0.0
142.6740,-2.0
142.7700,2.0
142.8660,-3.0
142.9620,0.0
143.0580,-3.0
143.1540,-5.0
143.2500,-1.0
143.3460,4.0
143.4420,7.0
143.5380,4.0
143.6340,14.0
143.7300,2.0
143.8260,1.0
143.9220,11.0
144.0180,9.0
144.1140,9.0
144.2100,9.0
144.3060,-8.0
144.4020,-6.0
144.4980,-3.0
144.5940,3.0
144.6900,-4.0
144.7860,5.0
144.8820,4.0
144.9780,3.0
145.0740,8.0
145.1700,-3.0
145.2660,12.0
145.3620,1.0
145.4580,2.0
145.5540,0.0
145.6500,8.0
145.7460,2.0
145.8420,1.0
145.9380,7.0
146.0340,3.0
146.1300,-3.0
146.2260,6.0
146.3220,8.0
146.4180,7.0
146.5140,10.0
146.6100,8.0
146.7060,9.0
146.8020,4.0
146.8980,-1.0
146.9940,3.0
147.0900,2.0
147.1860,-4.0
147.2820,7.0
147.3780,3.0
147.4740,2.0
147.5700,1.0
147.6660,2.0
147.7620,-2.0
147.8580,-2.0
147.9540,-2.0
148.0500,-6.0
148.1460,-6.0
148.2420,3.0
148.3380,0.0
148.4340,-11.0
148.5300,-2.0
148.6260,-5.0
148.7220,2.0
148.8180,1.0
148.9140,-5.0
149.0100,-3.0
149.1060,-5.0
149.2020,-10.0
149.2980,-7.0
149.3940,-6.0
149.4900,-1.0
149.5860,-5.0
149.6820,-7.0
149.7780,-9.0
149.8740,6.0
149.9700,5.0
150.0020,0.0