File: Input XRD/Control_Ti64.csv
[Measurement conditions]
Sample identification,CET
Comment - 1,"CET"
Comment - 2,"Configuration=MPSS New Configuration, Owner=User-1, Creation date=10/27/2010 9:00:11 AM"
Comment - 3,"Goniometer=PW3050/60 (Theta/Theta); Minimum step size 2Theta:0.001; Minimum step size Omega:0.001"
Comment - 4,"Sample stage=Multi purpose sample stage; Minimum step size Phi:2.5"
Comment - 5,"Diffractometer system=XPERT-PRO"
Comment - 6,"Measurement program=C:\PANalytical\Data Collector\Programs\ahansen\Ti Quick Scan.xrdmp, Identifier={1EDA9E56-6CAC-4C10-A94C-4527EDCC5A5B}"
Comment - 7,"PHD Lower Level = 6.04 (keV), PHD Upper Level = 12.80 (keV)"
Anode material,Cu
K-Alpha1 wavelength,1.5405980
K-Alpha2 wavelength,1.5444260
Ratio K-Alpha2/K-Alpha1,0.500
Divergence slit,Fixed,0.109
Receiving slit,0.10
Monochromator used,NO
Generator voltage, 45
Tube current, 40
File date and time,23/Jun/2021 13:12
Unit cell,
h k l, 0 0 0
Temperature [K],298
Scan axis,Gonio
Scan range,10.0000,150.0000
Scan step size,0.0080000
No. of points, 17500
Scan type,CONTINUOUS
Time per step,3.810
[Scan points]
Angle,Intensity
10.0040,0.0
10.1000,7.0
10.1960,-8.0
10.2920,-8.0
10.3880,-2.0
10.4840,-9.0
10.5800,-17.0
10.6760,-18.0
10.7720,-24.0
10.8680,-5.0
10.9640,1.0
11.0600,-7.0
11.1560,-6.0
11.2520,-10.0
11.3480,0.0
11.4440,3.0
11.5400,0.0
11.6360,0.0
11.7320,-5.0
11.8280,17.0
11.9240,-8.0
12.0200,1.0
12.1160,-1.0
12.2120,2.0
12.3080,0.0
12.4040,7.0
12.5000,-1.0
12.5960,-9.0
12.6920,-5.0
12.7880,-1.0
12.8840,6.0
12.9800,0.0
13.0760,5.0
13.1720,-3.0
13.2680,16.0
13.3640,2.0
13.4600,13.0
13.5560,4.0
13.6520,-9.0
13.7480,6.0
13.8440,0.0
13.9400,8.0
14.0360,-5.0
14.1320,-7.0
14.2280,3.0
14.3240,-9.0
14.4200,4.0
14.5160,-3.0
14.6120,9.0
14.7080,-7.0
14.8040,5.0
14.9000,3.0
14.9960,-3.0
15.0920,-3.0
15.1880,-5.0
15.2840,-15.0
15.3800,4.0
15.4760,10.0
15.5720,-3.0
15.6680,-2.0
15.7640,-3.0
15.8600,5.0
15.9560,3.0
16.0520,-19.0
16.1480,1.0
16.2440,-10.0
16.3400,6.0
16.4360,2.0
16.5320,-4.0
16.6280,5.0
16.7240,-5.0
16.8200,7.0
16.9160,2.0
17.0120,-2.0
17.1080,-4.0
17.2040,1.0
17.3000,0.0
17.3960,3.0
17.4920,-4.0
17.5880,2.0
17.6840,-6.0
17.7800,-5.0
17.8760,4.0
17.9720,-3.0
18.0680,-5.0
18.1640,-8.0
18.2600,-1.0
18.3560,9.0
18.4520,-6.0
18.5480,10.0
18.6440,2.0
18.7400,-9.0
18.8360,-8.0
18.9320,-2.0
19.0280,7.0
19.1240,2.0
19.2200,-2.0
19.3160,1.0
19.4120,4.0
19.5080,4.0
19.6040,0.0
19.7000,2.0
19.7960,1.0
19.8920,4.0
19.9880,0.0
20.0840,4.0
20.1800,-4.0
20.2760,-3.0
20.3720,10.0
20.4680,6.0
20.5640,10.0
20.6600,6.0
20.7560,6.0
20.8520,9.0
20.9480,-3.0
21.0440,5.0
21.1400,-5.0
21.2360,7.0
21.3320,5.0
21.4280,5.0
21.5240,8.0
21.6200,-1.0
21.7160,2.0
21.8120,-4.0
21.9080,9.0
22.0040,11.0
22.1000,3.0
22.1960,14.0
22.2920,0.0
22.3880,6.0
22.4840,-1.0
22.5800,14.0
22.6760,6.0
22.7720,1.0
22.8680,0.0
22.9640,12.0
23.0600,-1.0
23.1560,-1.0
23.2520,2.0
23.3480,-4.0
23.4440,4.0
23.5400,6.0
23.6360,-4.0
23.7320,7.0
23.8280,-4.0
23.9240,-6.0
24.0200,5.0
24.1160,8.0
24.2120,-3.0
24.3080,-4.0
24.4040,2.0
24.5000,-3.0
24.5960,-7.0
24.6920,5.0
24.7880,-4.0
24.8840,-1.0
24.9800,-2.0
25.0760,9.0
25.1720,5.0
25.2680,-9.0
25.3640,8.0
25.4600,-6.0
25.5560,-2.0
25.6520,-7.0
25.7480,-7.0
25.8440,-10.0
25.9400,-5.0
26.0360,1.0
26.1320,-5.0
26.2280,-8.0
26.3240,3.0
26.4200,-1.0
26.5160,-3.0
26.6120,-4.0
26.7080,-7.0
26.8040,-5.0
26.9000,-7.0
26.9960,-5.0
27.0920,-11.0
27.1880,-6.0
27.2840,-2.0
27.3800,-2.0
27.4760,-11.0
27.5720,2.0
27.6680,-3.0
27.7640,-5.0
27.8600,-9.0
27.9560,-4.0
28.0520,-1.0
28.1480,9.0
28.2440,0.0
28.3400,-8.0
28.4360,2.0
28.5320,2.0
28.6280,-2.0
28.7240,2.0
28.8200,-1.0
28.9160,0.0
29.0120,-3.0
29.1080,0.0
29.2040,7.0
29.3000,1.0
29.3960,-4.0
29.4920,6.0
29.5880,1.0
29.6840,-1.0
29.7800,6.0
29.8760,1.0
29.9720,2.0
30.0680,0.0
30.1640,3.0
30.2600,7.0
30.3560,7.0
30.4520,1.0
30.5480,0.0
30.6440,4.0
30.7400,9.0
30.8360,2.0
30.9320,-1.0
31.0280,-5.0
31.1240,-1.0
31.2200,-3.0
31.3160,2.0
31.4120,0.0
31.5080,2.0
31.6040,-2.0
31.7000,-9.0
31.7960,5.0
31.8920,-2.0
31.9880,-1.0
32.0840,1.0
32.1800,-3.0
32.2760,3.0
32.3720,3.0
32.4680,-2.0
32.5640,3.0
32.6600,3.0
32.7560,0.0
32.8520,1.0
32.9480,4.0
33.0440,2.0
33.1400,1.0
33.2360,7.0
33.3320,0.0
33.4280,2.0
33.5240,-4.0
33.6200,2.0
33.7160,4.0
33.8120,-2.0
33.9080,7.0
34.0040,1.0
34.1000,-5.0
34.1960,3.0
34.2920,0.0
34.3880,-6.0
34.4840,1.0
34.5800,1.0
34.6760,1.0
34.7720,-3.0
34.8680,3.0
34.9640,-2.0
35.0600,30.0
35.1560,94.0
35.2520,166.0
35.3480,215.0
35.4440,70.0
35.5400,12.0
35.6360,6.0
35.7320,-6.0
35.8280,1.0
35.9240,10.0
36.0200,-9.0
36.1160,-2.0
36.2120,12.0
36.3080,10.0
36.4040,2.0
36.5000,6.0
36.5960,-5.0
36.6920,3.0
36.7880,-1.0
36.8840,1.0
36.9800,-5.0
37.0760,0.0
37.1720,5.0
37.2680,-4.0
37.3640,3.0
37.4600,2.0
37.5560,3.0
37.6520,7.0
37.7480,3.0
37.8440,7.0
37.9400,10.0
38.0360,36.0
38.1320,95.0
38.2280,955.0
38.3240,3977.0
38.4200,1901.0
38.5160,197.0
38.6120,53.0
38.7080,15.0
38.8040,28.0
38.9000,28.0
38.9960,31.0
39.0920,87.0
39.1880,324.0
39.2840,913.0
39.3800,1131.0
39.4760,731.0
39.5720,335.0
39.6680,175.0
39.7640,114.0
39.8600,94.0
39.9560,100.0
40.0520,226.0
40.1480,806.0
40.2440,3927.0
40.3400,9137.0
40.4360,4921.0
40.5320,1079.0
40.6280,133.0
40.7240,50.0
40.8200,46.0
40.9160,25.0
41.0120,23.0
41.1080,7.0
41.2040,10.0
41.3000,7.0
41.3960,-6.0
41.4920,-3.0
41.5880,-2.0
41.6840,-6.0
41.7800,3.0
41.8760,-8.0
41.9720,-8.0
42.0680,-2.0
42.1640,-8.0
42.2600,-4.0
42.3560,12.0
42.4520,-2.0
42.5480,1.0
42.6440,0.0
42.7400,-13.0
42.8360,-1.0
42.9320,-9.0
43.0280,-3.0
43.1240,-3.0
43.2200,-6.0
43.3160,-3.0
43.4120,1.0
43.5080,0.0
43.6040,-1.0
43.7000,-4.0
43.7960,-4.0
43.8920,5.0
43.9880,-6.0
44.0840,4.0
44.1800,-7.0
44.2760,-3.0
44.3720,-3.0
44.4680,4.0
44.5640,-2.0
44.6600,1.0
44.7560,8.0
44.8520,-10.0
44.9480,0.0
45.0440,5.0
45.1400,6.0
45.2360,-1.0
45.3320,1.0
45.4280,0.0
45.5240,-9.0
45.6200,-5.0
45.7160,-2.0
45.8120,-5.0
45.9080,-2.0
46.0040,1.0
46.1000,-6.0
46.1960,-1.0
46.2920,-5.0
46.3880,-5.0
46.4840,10.0
46.5800,0.0
46.6760,7.0
46.7720,7.0
46.8680,-1.0
46.9640,0.0
47.0600,-2.0
47.1560,4.0
47.2520,-4.0
47.3480,1.0
47.4440,-7.0
47.5400,0.0
47.6360,1.0
47.7320,0.0
47.8280,-5.0
47.9240,-2.0
48.0200,-1.0
48.1160,-5.0
48.2120,-1.0
48.3080,-8.0
48.4040,-7.0
48.5000,-1.0
48.5960,-7.0
48.6920,-5.0
48.7880,2.0
48.8840,-6.0
48.9800,-2.0
49.0760,0.0
49.1720,-11.0
49.2680,7.0
49.3640,-7.0
49.4600,-4.0
49.5560,-4.0
49.6520,-7.0
49.7480,-5.0
49.8440,2.0
49.9400,4.0
50.0360,-5.0
50.1320,-4.0
50.2280,-4.0
50.3240,-2.0
50.4200,-1.0
50.5160,-4.0
50.6120,-5.0
50.7080,-4.0
50.8040,-1.0
50.9000,-2.0
50.9960,-6.0
51.0920,-8.0
51.1880,-2.0
51.2840,-8.0
51.3800,-12.0
51.4760,0.0
51.5720,-6.0
51.6680,-5.0
51.7640,-1.0
51.8600,-8.0
51.9560,-5.0
52.0520,-7.0
52.1480,0.0
52.2440,5.0
52.3400,-2.0
52.4360,-6.0
52.5320,-6.0
52.6280,-5.0
52.7240,-5.0
52.8200,-2.0
52.9160,-3.0
53.0120,0.0
53.1080,2.0
53.2040,4.0
53.3000,8.0
53.3960,5.0
53.4920,-3.0
53.5880,3.0
53.6840,1.0
53.7800,3.0
53.8760,-2.0
53.9720,-3.0
54.0680,-5.0
54.1640,2.0
54.2600,0.0
54.3560,8.0
54.4520,3.0
54.5480,14.0
54.6440,5.0
54.7400,1.0
54.8360,2.0
54.9320,11.0
55.0280,10.0
55.1240,-2.0
55.2200,9.0
55.3160,13.0
55.4120,-2.0
55.5080,-1.0
55.6040,9.0
55.7000,1.0
55.7960,1.0
55.8920,0.0
55.9880,1.0
56.0840,5.0
56.1800,-4.0
56.2760,2.0
56.3720,2.0
56.4680,-7.0
56.5640,1.0
56.6600,-4.0
56.7560,3.0
56.8520,-2.0
56.9480,1.0
57.0440,1.0
57.1400,-3.0
57.2360,2.0
57.3320,4.0
57.4280,1.0
57.5240,5.0
57.6200,5.0
57.7160,5.0
57.8120,8.0
57.9080,0.0
58.0040,-1.0
58.1000,6.0
58.1960,2.0
58.2920,9.0
58.3880,0.0
58.4840,0.0
58.5800,2.0
58.6760,9.0
58.7720,-2.0
58.8680,2.0
58.9640,2.0
59.0600,-11.0
59.1560,3.0
59.2520,5.0
59.3480,2.0
59.4440,5.0
59.5400,-1.0
59.6360,-1.0
59.7320,0.0
59.8280,-4.0
59.9240,-5.0
60.0200,5.0
60.1160,-5.0
60.2120,3.0
60.3080,-3.0
60.4040,3.0
60.5000,-1.0
60.5960,0.0
60.6920,4.0
60.7880,1.0
60.8840,-3.0
60.9800,-3.0
61.0760,4.0
61.1720,-3.0
61.2680,0.0
61.3640,4.0
61.4600,7.0
61.5560,1.0
61.6520,-1.0
61.7480,0.0
61.8440,8.0
61.9400,9.0
62.0360,2.0
62.1320,4.0
62.2280,4.0
62.3240,2.0
62.4200,-3.0
62.5160,5.0
62.6120,1.0
62.7080,0.0
62.8040,4.0
62.9000,-2.0
62.9960,3.0
63.0920,1.0
63.1880,9.0
63.2840,-1.0
63.3800,-2.0
63.4760,6.0
63.5720,2.0
63.6680,4.0
63.7640,0.0
63.8600,-1.0
63.9560,-7.0
64.0520,3.0
64.1480,-3.0
64.2440,-2.0
64.3400,0.0
64.4360,4.0
64.5320,1.0
64.6280,5.0
64.7240,-2.0
64.8200,-2.0
64.9160,-2.0
65.0120,-1.0
65.1080,-1.0
65.2040,1.0
65.3000,1.0
65.3960,1.0
65.4920,-1.0
65.5880,-1.0
65.6840,4.0
65.7800,1.0
65.8760,-7.0
65.9720,-8.0
66.0680,-1.0
66.1640,-2.0
66.2600,-1.0
66.3560,2.0
66.4520,-1.0
66.5480,3.0
66.6440,0.0
66.7400,1.0
66.8360,-1.0
66.9320,-5.0
67.0280,-3.0
67.1240,-2.0
67.2200,-3.0
67.3160,-10.0
67.4120,-6.0
67.5080,-1.0
67.6040,1.0
67.7000,-4.0
67.7960,-5.0
67.8920,-2.0
67.9880,5.0
68.0840,1.0
68.1800,9.0
68.2760,12.0
68.3720,-1.0
68.4680,6.0
68.5640,1.0
68.6600,-1.0
68.7560,12.0
68.8520,8.0
68.9480,4.0
69.0440,2.0
69.1400,2.0
69.2360,4.0
69.3320,-2.0
69.4280,0.0
69.5240,3.0
69.6200,0.0
69.7160,-3.0
69.8120,3.0
69.9080,1.0
70.0040,5.0
70.1000,4.0
70.1960,0.0
70.2920,1.0
70.3880,5.0
70.4840,-1.0
70.5800,4.0
70.6760,6.0
70.7720,9.0
70.8680,0.0
70.9640,2.0
71.0600,-8.0
71.1560,-8.0
71.2520,-2.0
71.3480,-2.0
71.4440,5.0
71.5400,-2.0
71.6360,-9.0
71.7320,-4.0
71.8280,3.0
71.9240,-1.0
72.0200,-11.0
72.1160,1.0
72.2120,-3.0
72.3080,1.0
72.4040,7.0
72.5000,0.0
72.5960,-5.0
72.6920,-2.0
72.7880,2.0
72.8840,1.0
72.9800,-2.0
73.0760,3.0
73.1720,3.0
73.2680,3.0
73.3640,1.0
73.4600,1.0
73.5560,2.0
73.6520,-1.0
73.7480,-4.0
73.8440,2.0
73.9400,13.0
74.0360,1.0
74.1320,-8.0
74.2280,3.0
74.3240,-1.0
74.4200,0.0
74.5160,4.0
74.6120,5.0
74.7080,11.0
74.8040,-3.0
74.9000,4.0
74.9960,-5.0
75.0920,-5.0
75.1880,0.0
75.2840,-2.0
75.3800,4.0
75.4760,3.0
75.5720,-3.0
75.6680,3.0
75.7640,-4.0
75.8600,-9.0
75.9560,5.0
76.0520,-3.0
76.1480,-3.0
76.2440,-8.0
76.3400,-7.0
76.4360,-5.0
76.5320,-4.0
76.6280,8.0
76.7240,10.0
76.8200,7.0
76.9160,23.0
77.0120,11.0
77.1080,4.0
77.2040,-3.0
77.3000,-5.0
77.3960,-4.0
77.4920,5.0
77.5880,2.0
77.6840,-6.0
77.7800,4.0
77.8760,9.0
77.9720,16.0
78.0680,17.0
78.1640,11.0
78.2600,10.0
78.3560,5.0
78.4520,2.0
78.5480,6.0
78.6440,1.0
78.7400,0.0
78.8360,0.0
78.9320,-3.0
79.0280,-8.0
79.1240,0.0
79.2200,-7.0
79.3160,-4.0
79.4120,0.0
79.5080,0.0
79.6040,-1.0
79.7000,0.0
79.7960,3.0
79.8920,-4.0
79.9880,-6.0
80.0840,-7.0
80.1800,4.0
80.2760,0.0
80.3720,-5.0
80.4680,-4.0
80.5640,-5.0
80.6600,1.0
80.7560,-5.0
80.8520,-4.0
80.9480,2.0
81.0440,1.0
81.1400,0.0
81.2360,-5.0
81.3320,-4.0
81.4280,-3.0
81.5240,1.0
81.6200,5.0
81.7160,-1.0
81.8120,0.0
81.9080,-3.0
82.0040,5.0
82.1000,-2.0
82.1960,7.0
82.2920,26.0
82.3880,127.0
82.4840,29.0
82.5800,24.0
82.6760,37.0
82.7720,14.0
82.8680,-3.0
82.9640,1.0
83.0600,-2.0
83.1560,1.0
83.2520,-4.0
83.3480,2.0
83.4440,0.0
83.5400,-4.0
83.6360,0.0
83.7320,-2.0
83.8280,-1.0
83.9240,1.0
84.0200,-3.0
84.1160,2.0
84.2120,-5.0
84.3080,-3.0
84.4040,7.0
84.5000,7.0
84.5960,2.0
84.6920,-5.0
84.7880,5.0
84.8840,14.0
84.9800,24.0
85.0760,17.0
85.1720,8.0
85.2680,9.0
85.3640,9.0
85.4600,5.0
85.5560,8.0
85.6520,2.0
85.7480,-4.0
85.8440,-5.0
85.9400,-1.0
86.0360,6.0
86.1320,-4.0
86.2280,-2.0
86.3240,-6.0
86.4200,-1.0
86.5160,1.0
86.6120,-6.0
86.7080,-4.0
86.8040,7.0
86.9000,-4.0
86.9960,-3.0
87.0920,2.0
87.1880,19.0
87.2840,68.0
87.3800,111.0
87.4760,127.0
87.5720,57.0
87.6680,77.0
87.7640,66.0
87.8600,10.0
87.9560,-3.0
88.0520,7.0
88.1480,-2.0
88.2440,-4.0
88.3400,-2.0
88.4360,-2.0
88.5320,-1.0
88.6280,6.0
88.7240,2.0
88.8200,7.0
88.9160,-3.0
89.0120,3.0
89.1080,-4.0
89.2040,8.0
89.3000,5.0
89.3960,-3.0
89.4920,-4.0
89.5880,1.0
89.6840,5.0
89.7800,-4.0
89.8760,-5.0
89.9720,0.0
90.0680,1.0
90.1640,2.0
90.2600,1.0
90.3560,-1.0
90.4520,4.0
90.5480,-10.0
90.6440,-4.0
90.7400,-4.0
90.8360,-4.0
90.9320,5.0
91.0280,-9.0
91.1240,-3.0
91.2200,-3.0
91.3160,0.0
91.4120,6.0
91.5080,3.0
91.6040,-4.0
91.7000,5.0
91.7960,4.0
91.8920,-1.0
91.9880,-1.0
92.0840,-1.0
92.1800,-2.0
92.2760,0.0
92.3720,-2.0
92.4680,6.0
92.5640,0.0
92.6600,0.0
92.7560,6.0
92.8520,2.0
92.9480,-1.0
93.0440,8.0
93.1400,2.0
93.2360,-2.0
93.3320,4.0
93.4280,-1.0
93.5240,1.0
93.6200,-1.0
93.7160,0.0
93.8120,-2.0
93.9080,-4.0
94.0040,-9.0
94.1000,1.0
94.1960,0.0
94.2920,2.0
94.3880,1.0
94.4840,1.0
94.5800,-1.0
94.6760,-6.0
94.7720,-5.0
94.8680,-5.0
94.9640,-4.0
95.0600,2.0
95.1560,-8.0
95.2520,-2.0
95.3480,-9.0
95.4440,1.0
95.5400,-3.0
95.6360,-1.0
95.7320,-8.0
95.8280,-3.0
95.9240,-3.0
96.0200,3.0
96.1160,6.0
96.2120,0.0
96.3080,-1.0
96.4040,-2.0
96.5000,-6.0
96.5960,-9.0
96.6920,1.0
96.7880,-5.0
96.8840,-4.0
96.9800,-3.0
97.0760,-1.0
97.1720,-4.0
97.2680,2.0
97.3640,0.0
97.4600,-4.0
97.5560,2.0
97.6520,-3.0
97.7480,5.0
97.8440,-1.0
97.9400,3.0
98.0360,7.0
98.1320,4.0
98.2280,-1.0
98.3240,-1.0
98.4200,-2.0
98.5160,-1.0
98.6120,3.0
98.7080,-5.0
98.8040,4.0
98.9000,-5.0
98.9960,-3.0
99.0920,3.0
99.1880,0.0
99.2840,3.0
99.3800,1.0
99.4760,1.0
99.5720,1.0
99.6680,-2.0
99.7640,0.0
99.8600,-7.0
99.9560,1.0
100.0520,3.0
100.1480,-5.0
100.2440,3.0
100.3400,3.0
100.4360,-2.0
100.5320,-2.0
100.6280,7.0
100.7240,-1.0
100.8200,0.0
100.9160,-2.0
101.0120,-4.0
101.1080,1.0
101.2040,0.0
101.3000,4.0
101.3960,6.0
101.4920,2.0
101.5880,5.0
101.6840,1.0
101.7800,-3.0
101.8760,-3.0
101.9720,7.0
102.0680,3.0
102.1640,1.0
102.2600,1.0
102.3560,4.0
102.4520,10.0
102.5480,-4.0
102.6440,2.0
102.7400,-9.0
102.8360,-6.0
102.9320,-2.0
103.0280,-2.0
103.1240,0.0
103.2200,-5.0
103.3160,0.0
103.4120,-4.0
103.5080,0.0
103.6040,6.0
103.7000,3.0
103.7960,-2.0
103.8920,0.0
103.9880,3.0
104.0840,2.0
104.1800,10.0
104.2760,5.0
104.3720,2.0
104.4680,5.0
104.5640,-2.0
104.6600,1.0
104.7560,2.0
104.8520,-1.0
104.9480,-3.0
105.0440,7.0
105.1400,3.0
105.2360,1.0
105.3320,-1.0
105.4280,1.0
105.5240,6.0
105.6200,-1.0
105.7160,-1.0
105.8120,3.0
105.9080,7.0
106.0040,2.0
106.1000,9.0
106.1960,2.0
106.2920,1.0
106.3880,0.0
106.4840,-7.0
106.5800,4.0
106.6760,2.0
106.7720,5.0
106.8680,4.0
106.9640,3.0
107.0600,5.0
107.1560,0.0
107.2520,3.0
107.3480,1.0
107.4440,4.0
107.5400,3.0
107.6360,4.0
107.7320,-3.0
107.8280,-4.0
107.9240,3.0
108.0200,8.0
108.1160,3.0
108.2120,-1.0
108.3080,-6.0
108.4040,2.0
108.5000,-1.0
108.5960,3.0
108.6920,7.0
108.7880,5.0
108.8840,-6.0
108.9800,0.0
109.0760,8.0
109.1720,-2.0
109.2680,1.0
109.3640,-1.0
109.4600,3.0
109.5560,2.0
109.6520,-3.0
109.7480,3.0
109.8440,1.0
109.9400,-3.0
110.0360,-3.0
110.1320,-3.0
110.2280,-2.0
110.3240,-1.0
110.4200,5.0
110.5160,-4.0
110.6120,-2.0
110.7080,-4.0
110.8040,-2.0
110.9000,-6.0
110.9960,-4.0
111.0920,-7.0
111.1880,-6.0
111.2840,-9.0
111.3800,1.0
111.4760,-8.0
111.5720,-6.0
111.6680,-2.0
111.7640,1.0
111.8600,-3.0
111.9560,-6.0
112.0520,-10.0
112.1480,-6.0
112.2440,-7.0
112.3400,-1.0
112.4360,0.0
112.5320,-3.0
112.6280,-4.0
112.7240,0.0
112.8200,-1.0
112.9160,-1.0
113.0120,6.0
113.1080,4.0
113.2040,-1.0
113.3000,0.0
113.3960,-3.0
113.4920,-9.0
113.5880,3.0
113.6840,-2.0
113.7800,3.0
113.8760,6.0
113.9720,2.0
114.0680,1.0
114.1640,5.0
114.2600,2.0
114.3560,-1.0
114.4520,-2.0
114.5480,3.0
114.6440,2.0
114.7400,-4.0
114.8360,3.0
114.9320,0.0
115.0280,0.0
115.1240,-1.0
115.2200,7.0
115.3160,-2.0
115.4120,4.0
115.5080,0.0
115.6040,5.0
115.7000,-1.0
115.7960,-2.0
115.8920,2.0
115.9880,2.0
116.0840,-1.0
116.1800,-6.0
116.2760,-3.0
116.3720,3.0
116.4680,-4.0
116.5640,4.0
116.6600,3.0
116.7560,-5.0
116.8520,-1.0
116.9480,-1.0
117.0440,-3.0
117.1400,-2.0
117.2360,-3.0
117.3320,-4.0
117.4280,-3.0
117.5240,3.0
117.6200,0.0
117.7160,-1.0
117.8120,1.0
117.9080,3.0
118.0040,4.0
118.1000,1.0
118.1960,0.0
118.2920,-2.0
118.3880,3.0
118.4840,7.0
118.5800,6.0
118.6760,-4.0
118.7720,-2.0
118.8680,-5.0
118.9640,-6.0
119.0600,-5.0
119.1560,-2.0
119.2520,-7.0
119.3480,-6.0
119.4440,4.0
119.5400,-4.0
119.6360,-2.0
119.7320,-3.0
119.8280,-5.0
119.9240,-7.0
120.0200,-5.0
120.1160,-7.0
120.2120,-4.0
120.3080,-4.0
120.4040,-1.0
120.5000,-4.0
120.5960,2.0
120.6920,-6.0
120.7880,-4.0
120.8840,-5.0
120.9800,-7.0
121.0760,-4.0
121.1720,-3.0
121.2680,4.0
121.3640,-4.0
121.4600,-1.0
121.5560,0.0
121.6520,-5.0
121.7480,-2.0
121.8440,0.0
121.9400,-4.0
122.0360,0.0
122.1320,0.0
122.2280,7.0
122.3240,2.0
122.4200,-4.0
122.5160,5.0
122.6120,4.0
122.7080,1.0
122.8040,4.0
122.9000,1.0
122.9960,9.0
123.0920,1.0
123.1880,4.0
123.2840,3.0
123.3800,0.0
123.4760,4.0
123.5720,-2.0
123.6680,-2.0
123.7640,8.0
123.8600,2.0
123.9560,1.0
124.0520,-6.0
124.1480,5.0
124.2440,1.0
124.3400,3.0
124.4360,2.0
124.5320,2.0
124.6280,8.0
124.7240,11.0
124.8200,5.0
124.9160,6.0
125.0120,10.0
125.1080,6.0
125.2040,8.0
125.3000,4.0
125.3960,1.0
125.4920,3.0
125.5880,-4.0
125.6840,7.0
125.7800,1.0
125.8760,5.0
125.9720,6.0
126.0680,1.0
126.1640,-2.0
126.2600,2.0
126.3560,8.0
126.4520,7.0
126.5480,-4.0
126.6440,0.0
126.7400,4.0
126.8360,0.0
126.9320,10.0
127.0280,3.0
127.1240,3.0
127.2200,1.0
127.3160,3.0
127.4120,4.0
127.5080,11.0
127.6040,6.0
127.7000,9.0
127.7960,-1.0
127.8920,9.0
127.9880,4.0
128.0840,4.0
128.1800,6.0
128.2760,2.0
128.3720,4.0
128.4680,0.0
128.5640,-2.0
128.6600,0.0
128.7560,-4.0
128.8520,-1.0
128.9480,-2.0
129.0440,2.0
129.1400,3.0
129.2360,0.0
129.3320,5.0
129.4280,4.0
129.5240,2.0
129.6200,4.0
129.7160,3.0
129.8120,0.0
129.9080,1.0
130.0040,3.0
130.1000,-3.0
130.1960,-1.0
130.2920,1.0
130.3880,-3.0
130.4840,-6.0
130.5800,-2.0
130.6760,1.0
130.7720,-10.0
130.8680,-1.0
130.9640,-5.0
131.0600,0.0
131.1560,-2.0
131.2520,-1.0
131.3480,-5.0
131.4440,7.0
131.5400,2.0
131.6360,1.0
131.7320,2.0
131.8280,-1.0
131.9240,8.0
132.0200,10.0
132.1160,-1.0
132.2120,-4.0
132.3080,-2.0
132.4040,2.0
132.5000,2.0
132.5960,0.0
132.6920,3.0
132.7880,-4.0
132.8840,-1.0
132.9800,-4.0
133.0760,-9.0
133.1720,4.0
133.2680,0.0
133.3640,2.0
133.4600,-2.0
133.5560,-3.0
133.6520,3.0
133.7480,4.0
133.8440,0.0
133.9400,0.0
134.0360,11.0
134.1320,5.0
134.2280,4.0
134.3240,-3.0
134.4200,-1.0
134.5160,3.0
134.6120,2.0
134.7080,5.0
134.8040,4.0
134.9000,0.0
134.9960,-1.0
135.0920,-1.0
135.1880,-3.0
135.2840,5.0
135.3800,9.0
135.4760,-1.0
135.5720,3.0
135.6680,-2.0
135.7640,0.0
135.8600,5.0
135.9560,-3.0
136.0520,5.0
136.1480,5.0
136.2440,-1.0
136.3400,2.0
136.4360,1.0
136.5320,-4.0
136.6280,7.0
136.7240,8.0
136.8200,1.0
136.9160,7.0
137.0120,-4.0
137.1080,-6.0
137.2040,-2.0
137.3000,4.0
137.3960,5.0
137.4920,-2.0
137.5880,-3.0
137.6840,-5.0
137.7800,-3.0
137.8760,0.0
137.9720,2.0
138.0680,0.0
138.1640,-1.0
138.2600,5.0
138.3560,1.0
138.4520,5.0
138.5480,-4.0
138.6440,-6.0
138.7400,-9.0
138.8360,-3.0
138.9320,3.0
139.0280,-2.0
139.1240,1.0
139.2200,-2.0
139.3160,11.0
139.4120,-2.0
139.5080,-13.0
139.6040,3.0
139.7000,-2.0
139.7960,-4.0
139.8920,1.0
139.9880,-2.0
140.0840,4.0
140.1800,3.0
140.2760,-8.0
140.3720,-4.0
140.4680,-6.0
140.5640,-5.0
140.6600,-3.0
140.7560,-3.0
140.8520,-2.0
140.9480,5.0
141.0440,8.0
141.1400,20.0
141.2360,23.0
141.3320,36.0
141.4280,58.0
141.5240,64.0
141.6200,84.0
141.7160,86.0
141.8120,56.0
141.9080,48.0
142.0040,25.0
142.1000,34.0
142.1960,29.0
142.2920,24.0
142.3880,34.0
142.4840,40.0
142.5800,38.0
142.6760,26.0
142.7720,19.0
142.8680,4.0
142.9640,5.0
143.0600,-2.0
143.1560,1.0
143.2520,-12.0
143.3480,-2.0
143.4440,-3.0
143.5400,-9.0
143.6360,6.0
143.7320,-3.0
143.8280,-6.0
143.9240,-4.0
144.0200,1.0
144.1160,1.0
144.2120,-2.0
144.3080,4.0
144.4040,8.0
144.5000,1.0
144.5960,-2.0
144.6920,4.0
144.7880,1.0
144.8840,2.0
144.9800,-2.0
145.0760,-1.0
145.1720,-8.0
145.2680,3.0
145.3640,-1.0
145.4600,-5.0
145.5560,-7.0
145.6520,6.0
145.7480,-9.0
145.8440,3.0
145.9400,4.0
146.0360,-4.0
146.1320,-2.0
146.2280,-5.0
146.3240,-3.0
146.4200,-3.0
146.5160,-8.0
146.6120,-3.0
146.7080,2.0
146.8040,-5.0
146.9000,-6.0
146.9960,3.0
147.0920,-3.0
147.1880,-11.0
147.2840,-4.0
147.3800,5.0
147.4760,-6.0
147.5720,-9.0
147.6680,1.0
147.7640,-9.0
147.8600,2.0
147.9560,-12.0
148.0520,1.0
148.1480,-3.0
148.2440,-1.0
148.3400,-1.0
148.4360,-2.0
148.5320,3.0
148.6280,-5.0
148.7240,7.0
148.8200,-3.0
148.9160,0.0
149.0120,0.0
149.1080,-6.0
149.2040,-4.0
149.3000,-9.0
149.3960,-1.0
149.4920,-7.0
149.5880,4.0
149.6840,1.0
149.7800,-4.0
149.8760,0.0
149.9720,0.0
149.9960,0.0